Workbook

Sheet Executive Briefing & Report
A1: EXECUTIVE BRIEFING & INCIDENT POST-MORTEM REPORT
A2: Prepared for: CTO, VP of Infrastructure, and Head of Financial Operations (FinOps)
A4: 1. EXECUTIVE SUMMARY & KEY FINDINGS
A5: During the September 2026 billing cycle audit across enterprise cloud infrastructure, the automated Statistical Anomaly Engine identified 5 critical 3-Sigma cost spikes totaling $313,900.00 in unbudgeted spend.
A6: While routine operational spend maintained a stable median of $4,200.00 per line item, runaway compute scaling and unindexed queries pushed the overall arithmetic mean to $6,136.67, causing a severe positive skewness ratio of 1.46x.
A7: All 5 anomalies exceeded the statistical Upper Control Limit (+3σ threshold of $34,535.54) with individual Z-scores ranging from +4.34σ to +8.05σ above baseline.
A9: 2. ANOMALY INCIDENT BREAKDOWN & ROOT CAUSE ANALYSIS
A10: • Incident #1 (BigQuery Slot Spike - $68,500.00 | Z-Score: +6.59σ): An unoptimized analytical query loop in Enterprise SaaS executed unindexed full-table scans over 450TB of raw log tables.
A11: • Incident #2 (Compute Engine GPU Spike - $82,400.00 | Z-Score: +8.05σ): E-Commerce Engine autoscaling group failed to trigger scale-in policies during off-peak weekend hours.
A12: • Incident #3 (GKE Data Egress Loop - $54,200.00 | Z-Score: +5.08σ): Misconfigured Kubernetes service mesh in Global Logistics routed inter-pod traffic across public internet gateways.
A13: • Incident #4 (Cloud SQL Replication Surge - $47,800.00 | Z-Score: +4.40σ): Hardware & IoT triggered unexpected cross-region read-replica syncs following a regional failover test.
A14: • Incident #5 (BigQuery Full Table Scan - $61,000.00 | Z-Score: +5.79σ): Pro Services executed unthrottled ad-hoc queries against unpartitioned billing export partitions.
... A20: 4. Commitment Discount Optimization: Allocate $3,500.00 in unblended promotional credits directly against Enterprise SaaS compute costs.

Sheet Executive Anomaly Dashboard
A1: ENTERPRISE GCP COST ANOMALY COMMAND CENTER
A2: Real-time cost spike monitoring, multi-dimensional business unit breakdown, and row-by-row audit log.
A4: TOTAL GROSS SPEND | D4: ACTIVE 3-SIGMA ANOMALIES | G4: TOTAL UNBLENDED CREDITS | J4: SKEWNESS RATIO (MEAN/MEDIAN)
A5: =SUM('Master Cleaned Data Pipeline'!G5:G499) | D5: =COUNTIF(F10:F504, "🚨 ANOMALY SPIKE") | G5: =SUMIF('Master Cleaned Data Pipeline'!J5:J499, "CREDIT / ADJUSTMENT", 'Master Cleaned Data Pipeline'!G5:G499) | J5: ='Stats & 3-Sigma Control Bounds'!C6 / 'Stats & 3-Sigma Control Bounds'!C7
A8: ROW-BY-ROW AUTOMATED COST ANOMALY AUDIT LOG
A9: TXN ID | B9: Date | C9: Cleaned Business Unit | D9: GCP Service | E9: Line Item Spend ($) | F9: 3-Sigma Anomaly Status | G9: Z-Score Distance | H9: FinOps Audit Recommendation
A10: ='Master Cleaned Data Pipeline'!A5 | B10: ='Master Cleaned Data Pipeline'!B5 | C10: ='Master Cleaned Data Pipeline'!I5 | D10: ='Master Cleaned Data Pipeline'!F5 | E10: ='Master Cleaned Data Pipeline'!G5 | F10: =IF(E10>'Stats & 3-Sigma Control Bounds'!$C$21, "🚨 ANOMALY SPIKE", IF(E10<0, "💳 CREDIT", "NORMAL")) | G10: =(E10-'Stats & 3-Sigma Control Bounds'!$C$6)/'Stats & 3-Sigma Control Bounds'!$C$9 | H10: =IF(F10="🚨 ANOMALY SPIKE", "IMMEDIATE ESCALATION TO ENGINEERING", IF(F10="💳 CREDIT", "AUDIT CREDIT ALLOCATION", "APPROVED USAGE"))
A11: ='Master Cleaned Data Pipeline'!A6 | B11: ='Master Cleaned Data Pipeline'!B6 | C11: ='Master Cleaned Data Pipeline'!I6 | D11: ='Master Cleaned Data Pipeline'!F6 | E11: ='Master Cleaned Data Pipeline'!G6 | F11: =IF(E11>'Stats & 3-Sigma Control Bounds'!$C$21, "🚨 ANOMALY SPIKE", IF(E11<0, "💳 CREDIT", "NORMAL")) | G11: =(E11-'Stats & 3-Sigma Control Bounds'!$C$6)/'Stats & 3-Sigma Control Bounds'!$C$9 | H11: =IF(F11="🚨 ANOMALY SPIKE", "IMMEDIATE ESCALATION TO ENGINEERING", IF(F11="💳 CREDIT", "AUDIT CREDIT ALLOCATION", "APPROVED USAGE"))
A12: ='Master Cleaned Data Pipeline'!A7 | B12: ='Master Cleaned Data Pipeline'!B7 | C12: ='Master Cleaned Data Pipeline'!I7 | D12: ='Master Cleaned Data Pipeline'!F7 | E12: ='Master Cleaned Data Pipeline'!G7 | F12: =IF(E12>'Stats & 3-Sigma Control Bounds'!$C$21, "🚨 ANOMALY SPIKE", IF(E12<0, "💳 CREDIT", "NORMAL")) | G12: =(E12-'Stats & 3-Sigma Control Bounds'!$C$6)/'Stats & 3-Sigma Control Bounds'!$C$9 | H12: =IF(F12="🚨 ANOMALY SPIKE", "IMMEDIATE ESCALATION TO ENGINEERING", IF(F12="💳 CREDIT", "AUDIT CREDIT ALLOCATION", "APPROVED USAGE"))
A13: ='Master Cleaned Data Pipeline'!A8 | B13: ='Master Cleaned Data Pipeline'!B8 | C13: ='Master Cleaned Data Pipeline'!I8 | D13: ='Master Cleaned Data Pipeline'!F8 | E13: ='Master Cleaned Data Pipeline'!G8 | F13: =IF(E13>'Stats & 3-Sigma Control Bounds'!$C$21, "🚨 ANOMALY SPIKE", IF(E13<0, "💳 CREDIT", "NORMAL")) | G13: =(E13-'Stats & 3-Sigma Control Bounds'!$C$6)/'Stats & 3-Sigma Control Bounds'!$C$9 | H13: =IF(F13="🚨 ANOMALY SPIKE", "IMMEDIATE ESCALATION TO ENGINEERING", IF(F13="💳 CREDIT", "AUDIT CREDIT ALLOCATION", "APPROVED USAGE"))
A14: ='Master Cleaned Data Pipeline'!A9 | B14: ='Master Cleaned Data Pipeline'!B9 | C14: ='Master Cleaned Data Pipeline'!I9 | D14: ='Master Cleaned Data Pipeline'!F9 | E14: ='Master Cleaned Data Pipeline'!G9 | F14: =IF(E14>'Stats & 3-Sigma Control Bounds'!$C$21, "🚨 ANOMALY SPIKE", IF(E14<0, "💳 CREDIT", "NORMAL")) | G14: =(E14-'Stats & 3-Sigma Control Bounds'!$C$6)/'Stats & 3-Sigma Control Bounds'!$C$9 | H14: =IF(F14="🚨 ANOMALY SPIKE", "IMMEDIATE ESCALATION TO ENGINEERING", IF(F14="💳 CREDIT", "AUDIT CREDIT ALLOCATION", "APPROVED USAGE"))
A15: ='Master Cleaned Data Pipeline'!A10 | B15: ='Master Cleaned Data Pipeline'!B10 | C15: ='Master Cleaned Data Pipeline'!I10 | D15: ='Master Cleaned Data Pipeline'!F10 | E15: ='Master Cleaned Data Pipeline'!G10 | F15: =IF(E15>'Stats & 3-Sigma Control Bounds'!$C$21, "🚨 ANOMALY SPIKE", IF(E15<0, "💳 CREDIT", "NORMAL")) | G15: =(E15-'Stats & 3-Sigma Control Bounds'!$C$6)/'Stats & 3-Sigma Control Bounds'!$C$9 | H15: =IF(F15="🚨 ANOMALY SPIKE", "IMMEDIATE ESCALATION TO ENGINEERING", IF(F15="💳 CREDIT", "AUDIT CREDIT ALLOCATION", "APPROVED USAGE"))
A16: ='Master Cleaned Data Pipeline'!A11 | B16: ='Master Cleaned Data Pipeline'!B11 | C16: ='Master Cleaned Data Pipeline'!I11 | D16: ='Master Cleaned Data Pipeline'!F11 | E16: ='Master Cleaned Data Pipeline'!G11 | F16: =IF(E16>'Stats & 3-Sigma Control Bounds'!$C$21, "🚨 ANOMALY SPIKE", IF(E16<0, "💳 CREDIT", "NORMAL")) | G16: =(E16-'Stats & 3-Sigma Control Bounds'!$C$6)/'Stats & 3-Sigma Control Bounds'!$C$9 | H16: =IF(F16="🚨 ANOMALY SPIKE", "IMMEDIATE ESCALATION TO ENGINEERING", IF(F16="💳 CREDIT", "AUDIT CREDIT ALLOCATION", "APPROVED USAGE"))
A17: ='Master Cleaned Data Pipeline'!A12 | B17: ='Master Cleaned Data Pipeline'!B12 | C17: ='Master Cleaned Data Pipeline'!I12 | D17: ='Master Cleaned Data Pipeline'!F12 | E17: ='Master Cleaned Data Pipeline'!G12 | F17: =IF(E17>'Stats & 3-Sigma Control Bounds'!$C$21, "🚨 ANOMALY SPIKE", IF(E17<0, "💳 CREDIT", "NORMAL")) | G17: =(E17-'Stats & 3-Sigma Control Bounds'!$C$6)/'Stats & 3-Sigma Control Bounds'!$C$9 | H17: =IF(F17="🚨 ANOMALY SPIKE", "IMMEDIATE ESCALATION TO ENGINEERING", IF(F17="💳 CREDIT", "AUDIT CREDIT ALLOCATION", "APPROVED USAGE"))
A18: ='Master Cleaned Data Pipeline'!A13 | B18: ='Master Cleaned Data Pipeline'!B13 | C18: ='Master Cleaned Data Pipeline'!I13 | D18: ='Master Cleaned Data Pipeline'!F13 | E18: ='Master Cleaned Data Pipeline'!G13 | F18: =IF(E18>'Stats & 3-Sigma Control Bounds'!$C$21, "🚨 ANOMALY SPIKE", IF(E18<0, "💳 CREDIT", "NORMAL")) | G18: =(E18-'Stats & 3-Sigma Control Bounds'!$C$6)/'Stats & 3-Sigma Control Bounds'!$C$9 | H18: =IF(F18="🚨 ANOMALY SPIKE", "IMMEDIATE ESCALATION TO ENGINEERING", IF(F18="💳 CREDIT", "AUDIT CREDIT ALLOCATION", "APPROVED USAGE"))
A19: ='Master Cleaned Data Pipeline'!A14 | B19: ='Master Cleaned Data Pipeline'!B14 | C19: ='Master Cleaned Data Pipeline'!I14 | D19: ='Master Cleaned Data Pipeline'!F14 | E19: ='Master Cleaned Data Pipeline'!G14 | F19: =IF(E19>'Stats & 3-Sigma Control Bounds'!$C$21, "🚨 ANOMALY SPIKE", IF(E19<0, "💳 CREDIT", "NORMAL")) | G19: =(E19-'Stats & 3-Sigma Control Bounds'!$C$6)/'Stats & 3-Sigma Control Bounds'!$C$9 | H19: =IF(F19="🚨 ANOMALY SPIKE", "IMMEDIATE ESCALATION TO ENGINEERING", IF(F19="💳 CREDIT", "AUDIT CREDIT ALLOCATION", "APPROVED USAGE"))
A20: ='Master Cleaned Data Pipeline'!A15 | B20: ='Master Cleaned Data Pipeline'!B15 | C20: ='Master Cleaned Data Pipeline'!I15 | D20: ='Master Cleaned Data Pipeline'!F15 | E20: ='Master Cleaned Data Pipeline'!G15 | F20: =IF(E20>'Stats & 3-Sigma Control Bounds'!$C$21, "🚨 ANOMALY SPIKE", IF(E20<0, "💳 CREDIT", "NORMAL")) | G20: =(E20-'Stats & 3-Sigma Control Bounds'!$C$6)/'Stats & 3-Sigma Control Bounds'!$C$9 | H20: =IF(F20="🚨 ANOMALY SPIKE", "IMMEDIATE ESCALATION TO ENGINEERING", IF(F20="💳 CREDIT", "AUDIT CREDIT ALLOCATION", "APPROVED USAGE"))
A21: ='Master Cleaned Data Pipeline'!A16 | B21: ='Master Cleaned Data Pipeline'!B16 | C21: ='Master Cleaned Data Pipeline'!I16 | D21: ='Master Cleaned Data Pipeline'!F16 | E21: ='Master Cleaned Data Pipeline'!G16 | F21: =IF(E21>'Stats & 3-Sigma Control Bounds'!$C$21, "🚨 ANOMALY SPIKE", IF(E21<0, "💳 CREDIT", "NORMAL")) | G21: =(E21-'Stats & 3-Sigma Control Bounds'!$C$6)/'Stats & 3-Sigma Control Bounds'!$C$9 | H21: =IF(F21="🚨 ANOMALY SPIKE", "IMMEDIATE ESCALATION TO ENGINEERING", IF(F21="💳 CREDIT", "AUDIT CREDIT ALLOCATION", "APPROVED USAGE"))
... A504: ='Master Cleaned Data Pipeline'!A499 | B504: ='Master Cleaned Data Pipeline'!B499 | C504: ='Master Cleaned Data Pipeline'!I499 | D504: ='Master Cleaned Data Pipeline'!F499 | E504: ='Master Cleaned Data Pipeline'!G499 | F504: =IF(E504>'Stats & 3-Sigma Control Bounds'!$C$21, "🚨 ANOMALY SPIKE", IF(E504<0, "💳 CREDIT", "NORMAL")) | G504: =(E504-'Stats & 3-Sigma Control Bounds'!$C$6)/'Stats & 3-Sigma Control Bounds'!$C$9 | H504: =IF(F504="🚨 ANOMALY SPIKE", "IMMEDIATE ESCALATION TO ENGINEERING", IF(F504="💳 CREDIT", "AUDIT CREDIT ALLOCATION", "APPROVED USAGE"))

Sheet Stats & 3-Sigma Control Bounds
A1: STATISTICAL DISTRIBUTION & 3-SIGMA ANOMALY CONTROL BOUNDS
A2: Parametric baseline statistics and statistical process control bounds for enterprise GCP spend.
A4: PART 1: BASELINE SUMMARY STATISTICS (CLEANED SPEND)
A5: Statistical Metric | B5: Spreadsheet Formula Syntax | C5: Evaluated Value | D5: Analyst Benchmark Interpretation
A6: Mean (Average Daily Line Item Spend) | B6: =AVERAGE('Master Cleaned Data Pipeline'!G5:G499) | C6: =AVERAGE('Master Cleaned Data Pipeline'!G5:G499) | D6: Arithmetic balance point across all transactions
A7: Median (Typical Spend Baseline) | B7: =MEDIAN('Master Cleaned Data Pipeline'!G5:G499) | C7: =MEDIAN('Master Cleaned Data Pipeline'!G5:G499) | D7: 50th percentile robust measure (resists outlier skew)
A8: Sample Variance (S²) | B8: =VAR.S('Master Cleaned Data Pipeline'!G5:G499) | C8: =VAR.S('Master Cleaned Data Pipeline'!G5:G499) | D8: Average squared deviation from the mean (n-1 correction)
A9: Sample Standard Deviation (σ) | B9: =STDEV.S('Master Cleaned Data Pipeline'!G5:G499) | C9: =STDEV.S('Master Cleaned Data Pipeline'!G5:G499) | D9: Standard volatility measure expressed in dollar units
A10: Minimum Spend Record | B10: =MIN('Master Cleaned Data Pipeline'!G5:G499) | C10: =MIN('Master Cleaned Data Pipeline'!G5:G499) | D10: Largest negative credit adjustment in dataset
A11: Maximum Spend Record | B11: =MAX('Master Cleaned Data Pipeline'!G5:G499) | C11: =MAX('Master Cleaned Data Pipeline'!G5:G499) | D11: Largest single runaway cost spike in dataset
A12: Total Line Item Count (N) | B12: =COUNT('Master Cleaned Data Pipeline'!G5:G499) | C12: =COUNT('Master Cleaned Data Pipeline'!G5:G499) | D12: Total volume of processed billing line items
A15: PART 2: STATISTICAL CONTROL BOUNDS & ANOMALY THRESHOLDS
A16: Threshold Bound Level | B16: Mathematical Calculation Formula | C16: Dynamic Control Value | D16: Operational Guardrail Action
A17: Baseline Mean (μ) | B17: Mean from Part 1 (Cell C6) | C17: =C6 | D17: Normal operational spend balance point
A18: Standard Deviation (σ) | B18: StdDev from Part 1 (Cell C9) | C18: =C9 | D18: Standard daily volatility allowance
A19: 1-Sigma Upper Bound (+1σ) | B19: Mean + (1 * StdDev) | C19: =C17+(1*C18) | D19: 68.2% expected normal distribution boundary
A20: 2-Sigma Warning Bound (+2σ) | B20: Mean + (2 * StdDev) | C20: =C17+(2*C18) | D20: 95.4% boundary - High warning threshold
A21: 3-Sigma Upper Control Limit (+3σ) | B21: Mean + (3 * StdDev) | C21: =C17+(3*C18) | D21: 99.7% boundary - 🚨 AUTOMATED ANOMALY SPIKE ALARM

Sheet Master Cleaned Data Pipeline
A1: DATA CLEANING & GOVERNANCE PIPELINE LAYER
A2: Automated de-duplication, null business unit assertion, and line-item credit unblending logic.
A4: TXN ID | B4: Date | C4: Project ID | D4: Raw Business Unit | E4: Region | F4: GCP Service | G4: Raw Spend ($) | H4: Duplicate Flag (Task 1) | I4: Cleaned Business Unit (Task 2) | J4: Line Item Classification (Task 3)
A5: ='Raw Enterprise Billing Data'!A5 | B5: ='Raw Enterprise Billing Data'!B5 | C5: ='Raw Enterprise Billing Data'!C5 | D5: ='Raw Enterprise Billing Data'!D5 | E5: ='Raw Enterprise Billing Data'!E5 | F5: ='Raw Enterprise Billing Data'!F5 | G5: ='Raw Enterprise Billing Data'!H5 | H5: =IF(COUNTIF($A$5:$A$499, A5)>1, "⚠️ DUPLICATE", "UNIQUE") | I5: =IF(OR(ISBLANK(D5), D5=""), "Unassigned", D5) | J5: =IF(G5<0, "CREDIT / ADJUSTMENT", "STANDARD USAGE")
A6: ='Raw Enterprise Billing Data'!A6 | B6: ='Raw Enterprise Billing Data'!B6 | C6: ='Raw Enterprise Billing Data'!C6 | D6: ='Raw Enterprise Billing Data'!D6 | E6: ='Raw Enterprise Billing Data'!E6 | F6: ='Raw Enterprise Billing Data'!F6 | G6: ='Raw Enterprise Billing Data'!H6 | H6: =IF(COUNTIF($A$5:$A$499, A6)>1, "⚠️ DUPLICATE", "UNIQUE") | I6: =IF(OR(ISBLANK(D6), D6=""), "Unassigned", D6) | J6: =IF(G6<0, "CREDIT / ADJUSTMENT", "STANDARD USAGE")
A7: ='Raw Enterprise Billing Data'!A7 | B7: ='Raw Enterprise Billing Data'!B7 | C7: ='Raw Enterprise Billing Data'!C7 | D7: ='Raw Enterprise Billing Data'!D7 | E7: ='Raw Enterprise Billing Data'!E7 | F7: ='Raw Enterprise Billing Data'!F7 | G7: ='Raw Enterprise Billing Data'!H7 | H7: =IF(COUNTIF($A$5:$A$499, A7)>1, "⚠️ DUPLICATE", "UNIQUE") | I7: =IF(OR(ISBLANK(D7), D7=""), "Unassigned", D7) | J7: =IF(G7<0, "CREDIT / ADJUSTMENT", "STANDARD USAGE")
A8: ='Raw Enterprise Billing Data'!A8 | B8: ='Raw Enterprise Billing Data'!B8 | C8: ='Raw Enterprise Billing Data'!C8 | D8: ='Raw Enterprise Billing Data'!D8 | E8: ='Raw Enterprise Billing Data'!E8 | F8: ='Raw Enterprise Billing Data'!F8 | G8: ='Raw Enterprise Billing Data'!H8 | H8: =IF(COUNTIF($A$5:$A$499, A8)>1, "⚠️ DUPLICATE", "UNIQUE") | I8: =IF(OR(ISBLANK(D8), D8=""), "Unassigned", D8) | J8: =IF(G8<0, "CREDIT / ADJUSTMENT", "STANDARD USAGE")
A9: ='Raw Enterprise Billing Data'!A9 | B9: ='Raw Enterprise Billing Data'!B9 | C9: ='Raw Enterprise Billing Data'!C9 | D9: ='Raw Enterprise Billing Data'!D9 | E9: ='Raw Enterprise Billing Data'!E9 | F9: ='Raw Enterprise Billing Data'!F9 | G9: ='Raw Enterprise Billing Data'!H9 | H9: =IF(COUNTIF($A$5:$A$499, A9)>1, "⚠️ DUPLICATE", "UNIQUE") | I9: =IF(OR(ISBLANK(D9), D9=""), "Unassigned", D9) | J9: =IF(G9<0, "CREDIT / ADJUSTMENT", "STANDARD USAGE")
A10: ='Raw Enterprise Billing Data'!A10 | B10: ='Raw Enterprise Billing Data'!B10 | C10: ='Raw Enterprise Billing Data'!C10 | D10: ='Raw Enterprise Billing Data'!D10 | E10: ='Raw Enterprise Billing Data'!E10 | F10: ='Raw Enterprise Billing Data'!F10 | G10: ='Raw Enterprise Billing Data'!H10 | H10: =IF(COUNTIF($A$5:$A$499, A10)>1, "⚠️ DUPLICATE", "UNIQUE") | I10: =IF(OR(ISBLANK(D10), D10=""), "Unassigned", D10) | J10: =IF(G10<0, "CREDIT / ADJUSTMENT", "STANDARD USAGE")
A11: ='Raw Enterprise Billing Data'!A11 | B11: ='Raw Enterprise Billing Data'!B11 | C11: ='Raw Enterprise Billing Data'!C11 | D11: ='Raw Enterprise Billing Data'!D11 | E11: ='Raw Enterprise Billing Data'!E11 | F11: ='Raw Enterprise Billing Data'!F11 | G11: ='Raw Enterprise Billing Data'!H11 | H11: =IF(COUNTIF($A$5:$A$499, A11)>1, "⚠️ DUPLICATE", "UNIQUE") | I11: =IF(OR(ISBLANK(D11), D11=""), "Unassigned", D11) | J11: =IF(G11<0, "CREDIT / ADJUSTMENT", "STANDARD USAGE")
A12: ='Raw Enterprise Billing Data'!A12 | B12: ='Raw Enterprise Billing Data'!B12 | C12: ='Raw Enterprise Billing Data'!C12 | D12: ='Raw Enterprise Billing Data'!D12 | E12: ='Raw Enterprise Billing Data'!E12 | F12: ='Raw Enterprise Billing Data'!F12 | G12: ='Raw Enterprise Billing Data'!H12 | H12: =IF(COUNTIF($A$5:$A$499, A12)>1, "⚠️ DUPLICATE", "UNIQUE") | I12: =IF(OR(ISBLANK(D12), D12=""), "Unassigned", D12) | J12: =IF(G12<0, "CREDIT / ADJUSTMENT", "STANDARD USAGE")
A13: ='Raw Enterprise Billing Data'!A13 | B13: ='Raw Enterprise Billing Data'!B13 | C13: ='Raw Enterprise Billing Data'!C13 | D13: ='Raw Enterprise Billing Data'!D13 | E13: ='Raw Enterprise Billing Data'!E13 | F13: ='Raw Enterprise Billing Data'!F13 | G13: ='Raw Enterprise Billing Data'!H13 | H13: =IF(COUNTIF($A$5:$A$499, A13)>1, "⚠️ DUPLICATE", "UNIQUE") | I13: =IF(OR(ISBLANK(D13), D13=""), "Unassigned", D13) | J13: =IF(G13<0, "CREDIT / ADJUSTMENT", "STANDARD USAGE")
A14: ='Raw Enterprise Billing Data'!A14 | B14: ='Raw Enterprise Billing Data'!B14 | C14: ='Raw Enterprise Billing Data'!C14 | D14: ='Raw Enterprise Billing Data'!D14 | E14: ='Raw Enterprise Billing Data'!E14 | F14: ='Raw Enterprise Billing Data'!F14 | G14: ='Raw Enterprise Billing Data'!H14 | H14: =IF(COUNTIF($A$5:$A$499, A14)>1, "⚠️ DUPLICATE", "UNIQUE") | I14: =IF(OR(ISBLANK(D14), D14=""), "Unassigned", D14) | J14: =IF(G14<0, "CREDIT / ADJUSTMENT", "STANDARD USAGE")
A15: ='Raw Enterprise Billing Data'!A15 | B15: ='Raw Enterprise Billing Data'!B15 | C15: ='Raw Enterprise Billing Data'!C15 | D15: ='Raw Enterprise Billing Data'!D15 | E15: ='Raw Enterprise Billing Data'!E15 | F15: ='Raw Enterprise Billing Data'!F15 | G15: ='Raw Enterprise Billing Data'!H15 | H15: =IF(COUNTIF($A$5:$A$499, A15)>1, "⚠️ DUPLICATE", "UNIQUE") | I15: =IF(OR(ISBLANK(D15), D15=""), "Unassigned", D15) | J15: =IF(G15<0, "CREDIT / ADJUSTMENT", "STANDARD USAGE")
A16: ='Raw Enterprise Billing Data'!A16 | B16: ='Raw Enterprise Billing Data'!B16 | C16: ='Raw Enterprise Billing Data'!C16 | D16: ='Raw Enterprise Billing Data'!D16 | E16: ='Raw Enterprise Billing Data'!E16 | F16: ='Raw Enterprise Billing Data'!F16 | G16: ='Raw Enterprise Billing Data'!H16 | H16: =IF(COUNTIF($A$5:$A$499, A16)>1, "⚠️ DUPLICATE", "UNIQUE") | I16: =IF(OR(ISBLANK(D16), D16=""), "Unassigned", D16) | J16: =IF(G16<0, "CREDIT / ADJUSTMENT", "STANDARD USAGE")
... A499: ='Raw Enterprise Billing Data'!A499 | B499: ='Raw Enterprise Billing Data'!B499 | C499: ='Raw Enterprise Billing Data'!C499 | D499: ='Raw Enterprise Billing Data'!D499 | E499: ='Raw Enterprise Billing Data'!E499 | F499: ='Raw Enterprise Billing Data'!F499 | G499: ='Raw Enterprise Billing Data'!H499 | H499: =IF(COUNTIF($A$5:$A$499, A499)>1, "⚠️ DUPLICATE", "UNIQUE") | I499: =IF(OR(ISBLANK(D499), D499=""), "Unassigned", D499) | J499: =IF(G499<0, "CREDIT / ADJUSTMENT", "STANDARD USAGE")

Sheet Raw Enterprise Billing Data
A1: RAW UNCLEANED ENTERPRISE GCP BILLING EXPORT
A2: Ingested raw dataset containing 495 line items with intentional duplicate events, null business units, credits, and cost spikes.
A4: TXN ID | B4: Date | C4: Project ID | D4: Raw Business Unit | E4: Region | F4: GCP Service | G4: SKU Description | H4: Raw Spend ($) | I4: Record Status
A5: TXN-1149 | B5: 2026-09-30 | C5: prj-hardware-and-iot-104 | D5: Hardware & IoT | E5: southamerica-east1 | F5: Cloud Storage | G5: Standard Storage GB | H5: 1498.42 | I5: Active
A6: TXN-1294 | B6: 2026-09-29 | C6: prj-enterprise-saas-102 | D6: Enterprise SaaS | E6: us-central1 | F6: BigQuery | G6: Analysis Slot Usage | H6: 8592.3 | I6: Active
A7: TXN-1090 | B7: 2026-09-19 | C7: prj-global-logistics-104 | D7: Global Logistics | E7: us-east4 | F7: Cloud SQL | G7: PostgreSQL High Availability | H7: 3353.95 | I7: Active
A8: TXN-1159 | B8: 2026-09-23 | C8: prj-pro-services-105 | D8: Pro Services | E8: asia-east1 | F8: Cloud SQL | G8: PostgreSQL High Availability | H8: 2628.44 | I8: Active
A9: TXN-1181 | B9: 2026-09-02 | C9: prj-e-commerce-engine-103 | D9: E-Commerce Engine | E9: us-central1 | F9: Cloud Storage | G9: Standard Storage GB | H9: 3793.31 | I9: Active
A10: TXN-1070 | B10: 2026-09-30 | C10: prj-hardware-and-iot-103 | D10: Hardware & IoT | E10: us-east4 | F10: Cloud Storage | G10: Standard Storage GB | H10: 1613.91 | I10: Active
A11: TXN-1082 | B11: 2026-09-10 | C11: prj-e-commerce-engine-104 | D11: E-Commerce Engine | E11: europe-west1 | F11: Cloud Storage | G11: Standard Storage GB | H11: 2928.82 | I11: Active
A12: TXN-1108 | B12: 2026-09-05 | C12: prj-pro-services-103 | D12: Pro Services | E12: europe-west1 | F12: Compute Engine | G12: N2 Standard 8 vCPU | H12: 5016.42 | I12: Active
A13: TXN-1315 | B13: 2026-09-23 | C13: prj-pro-services-103 | D13: Pro Services | E13: europe-west1 | F13: Cloud SQL | G13: PostgreSQL High Availability | H13: 4064.95 | I13: Active
A14: TXN-1297 | B14: 2026-09-26 | C14: prj-e-commerce-engine-101 | D14: E-Commerce Engine | E14: us-east4 | F14: Compute Engine | G14: N2 Standard 8 vCPU | H14: 6846.75 | I14: Active
A15: TXN-1003 | B15: 2026-09-01 | C15: prj-enterprise-saas-105 | D15: Enterprise SaaS | E15: europe-west1 | F15: Cloud Storage | G15: Standard Storage GB | H15: 2765.25 | I15: Active
A16: TXN-1370 | B16: 2026-09-08 | C16: prj-enterprise-saas-102 | D16: Enterprise SaaS | E16: southamerica-east1 | F16: Compute Engine | G16: N2 Standard 8 vCPU | H16: 3575.75 | I16: Active
... A50: TXN-1216 | B50: 2026-09-05 | C50: prj-global-logistics-102 | D50: Global Logistics | E50: southamerica-east1 | F50: BigQuery | G50: Analysis Slot Usage | H50: 4604.59 | I50: Active
A51: TXN-1431 | B51: 2026-09-14 | C51: prj-e-commerce-engine-104 | E51: southamerica-east1 | F51: Cloud Storage | G51: Standard Storage GB | H51: 1831.43 | I51: Active
A52: TXN-9901 | B52: 2026-09-08 | C52: prj-enterprise-saas-101 | D52: Enterprise SaaS | E52: us-central1 | F52: BigQuery | G52: Slot Reservation Spike Anomaly | H52: 68500 | I52: Active
A53: TXN-1130 | B53: 2026-09-08 | C53: prj-pro-services-105 | D53: Pro Services | E53: europe-west1 | F53: BigQuery | G53: Analysis Slot Usage | H53: 6029.61 | I53: Active
A54: TXN-1084 | B54: 2026-09-27 | C54: prj-enterprise-saas-102 | D54: Enterprise SaaS | E54: asia-east1 | F54: BigQuery | G54: Analysis Slot Usage | H54: 6364.38 | I54: Active
A55: TXN-1219 | B55: 2026-09-05 | C55: prj-pro-services-101 | D55: Pro Services | E55: southamerica-east1 | F55: Compute Engine | G55: N2 Standard 8 vCPU | H55: 5404.98 | I55: Active
A56: TXN-1420 | B56: 2026-09-29 | C56: prj-enterprise-saas-101 | D56: Enterprise SaaS | E56: europe-west1 | F56: Cloud Storage | G56: Standard Storage GB | H56: 1462.33 | I56: Active
A57: TXN-1212 | B57: 2026-09-04 | C57: prj-pro-services-105 | D57: Pro Services | E57: us-central1 | F57: Cloud Storage | G57: Standard Storage GB | H57: 3724.84 | I57: Active
A58: TXN-1321 | B58: 2026-09-22 | C58: prj-pro-services-104 | D58: Pro Services | E58: asia-east1 | F58: BigQuery | G58: Analysis Slot Usage | H58: 8196.96 | I58: Active
A59: TXN-1139 | B59: 2026-09-16 | C59: prj-pro-services-102 | D59: Pro Services | E59: us-east4 | F59: BigQuery | G59: Analysis Slot Usage | H59: 9310.24 | I59: Active
A60: TXN-1055 | B60: 2026-09-10 | C60: prj-pro-services-101 | D60: Pro Services | E60: asia-east1 | F60: Compute Engine | G60: N2 Standard 8 vCPU | H60: 5333.14 | I60: Active
A61: TXN-1189 | B61: 2026-09-12 | C61: prj-e-commerce-engine-103 | D61: E-Commerce Engine | E61: asia-east1 | F61: Cloud SQL | G61: PostgreSQL High Availability | H61: 4098.93 | I61: Active
A62: TXN-1246 | B62: 2026-09-10 | C62: prj-e-commerce-engine-103 | D62: E-Commerce Engine | E62: us-east4 | F62: Google Kubernetes Engine | G62: Promotional Credit / Outage SLA Refund | H62: -1679.89 | I62: Active
A63: TXN-1214 | B63: 2026-09-27 | C63: prj-e-commerce-engine-102 | D63: E-Commerce Engine | E63: europe-west1 | F63: Google Kubernetes Engine | G63: Autopilot Pod Compute | H63: 9878.32 | I63: Active
... A73: TXN-1337 | B73: 2026-09-17 | C73: prj-hardware-and-iot-102 | D73: Hardware & IoT | E73: us-central1 | F73: BigQuery | G73: Analysis Slot Usage | H73: 7492.81 | I73: Active
A74: TXN-1070 | B74: 2026-09-30 | C74: prj-hardware-and-iot-103 | E74: us-east4 | F74: Cloud Storage | G74: Standard Storage GB | H74: 1613.91 | I74: Active
A75: TXN-1073 | B75: 2026-09-22 | C75: prj-global-logistics-103 | D75: Global Logistics | E75: us-east4 | F75: BigQuery | G75: Analysis Slot Usage | H75: 8753.94 | I75: Active
A76: TXN-1330 | B76: 2026-09-18 | C76: prj-e-commerce-engine-105 | D76: E-Commerce Engine | E76: asia-east1 | F76: Cloud SQL | G76: PostgreSQL High Availability | H76: 2954.2 | I76: Active
A77: TXN-1302 | B77: 2026-09-17 | C77: prj-e-commerce-engine-104 | D77: E-Commerce Engine | E77: us-central1 | F77: Cloud SQL | G77: PostgreSQL High Availability | H77: 2652.37 | I77: Active
A78: TXN-1368 | B78: 2026-09-26 | C78: prj-e-commerce-engine-101 | D78: E-Commerce Engine | E78: southamerica-east1 | F78: Cloud Storage | G78: Standard Storage GB | H78: 2717.16 | I78: Active
A79: TXN-1150 | B79: 2026-09-08 | C79: prj-global-logistics-101 | D79: Global Logistics | E79: asia-east1 | F79: Cloud Storage | G79: Promotional Credit / Outage SLA Refund | H79: -1339.46 | I79: Active
A80: TXN-1322 | B80: 2026-09-19 | C80: prj-global-logistics-104 | D80: Global Logistics | E80: southamerica-east1 | F80: BigQuery | G80: Analysis Slot Usage | H80: 5729.12 | I80: Active
A81: TXN-1134 | B81: 2026-09-23 | C81: prj-global-logistics-104 | D81: Global Logistics | E81: europe-west1 | F81: Cloud Storage | G81: Standard Storage GB | H81: 1918.9 | I81: Active
A82: TXN-1264 | B82: 2026-09-03 | C82: prj-hardware-and-iot-101 | D82: Hardware & IoT | E82: us-east4 | F82: Cloud SQL | G82: PostgreSQL High Availability | H82: 2699.12 | I82: Active
A83: TXN-1268 | B83: 2026-09-05 | C83: prj-enterprise-saas-103 | D83: Enterprise SaaS | E83: us-east4 | F83: Compute Engine | G83: N2 Standard 8 vCPU | H83: 7429.54 | I83: Active
...
